Workbook

Sheet README
A1: Scenarios and results: average reservoir pressure in shale without extended shut-in
A2: This workbook lists every scenario run for the manuscript and the result of each. All values are outputs of the code in 05_Code; nothing here needs to be edited.
A4: Sheets
A5: Scenario_Definitions — what each synthetic and field scenario changes, how many cases it has, and the random seeds used.
A6: Parameter_Ranges — sampling ranges of the main synthetic set and the overrides of the two out-of-distribution sets.
A7: Results_by_Scenario — accuracy of every estimator, for every scenario and buildup duration N (pooled out-of-fold for the main set).
A8: Summary — headline comparison computed with formulas from Results_by_Scenario.
A9: Initial_Pressure_Sensitivity — the 8 % versus 15 % initial-pressure-error scenario on the held-out selection-split cases.
A10: Field_Scenarios — HFTS-1 Monte Carlo results per well and buildup duration (P10 / P50 / P90 over 300 draws).
A11: Field_Rate_Variants — the three pad-production scenarios (older-well base decline slow / central / fast).
A13: Conventions
A14: Relative error e = (estimate − p̄_S) / (p̄_S − p_wf). 'Median |e|' is the median absolute value; 'Bias' is the median signed value.
... A16: Font colour: black values are model outputs; formulas on the Summary sheet recalculate from Results_by_Scenario.

Sheet Scenario_Definitions
A1: Scenario definitions
A3: ID | B3: Scenario | C3: Purpose | D3: Data | E3: Cases / wells | F3: Physics or parameter change | G3: Observation settings | H3: Random seeds | I3: Results
A4: S1 | B4: Main (in-distribution) | C4: Training, cross-validation and headline accuracy | D4: 03_Raw_Data/synthetic/main; 04_Clean_Data/synthetic/feature_table_main.csv | E4: 2997 | F4: Table 1 ranges; constant c_t | G4: N = 24, 72, 168 h; p_i error 8 % (1 s.d.); rate noise 5 %; gauge noise 0.1–1 psi | H4: simulation 20261024; observation 1 | I4: Results_by_Scenario (set = cv_pooled)
A5: S2 | B5: Nonlinear compressibility | C5: Robustness to free gas below a bubble point (out of distribution) | D5: 03_Raw_Data/synthetic/nonlinear; feature_table_nonlinear.csv | E5: 160 | F5: c_t rises 3–10× below p_b = 1,500–3,500 psia, Eq. (15) | G5: as S1 | H5: simulation 777; observation 5 | I5: Results_by_Scenario (set = nonlinear)
A6: S3 | B6: Extrapolation | C6: Spacing and permeability outside the training ranges | D6: 03_Raw_Data/synthetic/extrap; feature_table_extrap.csv | E6: 199 | F6: L = 150–300 ft; k = 3–10 μD (case 128 of 200 failed grid construction) | G6: as S1 | H6: simulation 999; observation 3 | I6: Results_by_Scenario (set = extrap)
A7: S4 | B7: Initial-pressure error 15 % | C7: Sensitivity of the estimators to a poorly known initial pressure | D7: feature_table_main_pierr15.csv | E7: 2997 | F7: same cases as S1 | G7: p_i error 15 % (1 s.d.) | H7: observation 1 | I7: Initial_Pressure_Sensitivity
A8: F1 | B8: HFTS-1, central pad-decline variant | C8: Field application | D8: 04_Clean_Data/field | E8: 10 | F8: older-well base decline 0.69 /yr | G8: p_i ~ U(3,700, 4,800) psia; 5 % rate noise; N = 24 h and min(72 h, buildup length) | H8: Monte Carlo 2016 (300 draws, variants cycled) | I8: Field_Scenarios
A9: F2 | B9: HFTS-1, slow pad-decline variant | C9: Field application | D9: 04_Clean_Data/field | E9: 10 | F9: base decline × 0.5 | G9: as F1 | H9: as F1 | I9: Field_Scenarios (pooled)
A10: F3 | B10: HFTS-1, fast pad-decline variant | C10: Field application | D10: 04_Clean_Data/field | E10: 10 | F10: base decline × 1.5 | G10: as F1 | H10: as F1 | I10: Field_Scenarios (pooled)

Sheet Parameter_Ranges
A1: Sampling ranges (Table 1) and out-of-distribution overrides
A3: Quantity | B3: Symbol | C3: Main set (S1, S4) | D3: Extrapolation set (S3) | E3: Nonlinear set (S2)
A4: Matrix permeability | B4: k | C4: 0.1–3 μD (log-uniform) | D4: 3–10 μD | E4: —
A5: Porosity | B5: φ | C5: 0.04–0.10 (uniform) | D5: — | E5: —
A6: Oil viscosity | B6: μ | C6: 0.2–1.0 cp (log-uniform) | D6: — | E6: —
A7: Total compressibility | B7: c_t | C7: 5×10⁻⁶–3×10⁻⁵ psi⁻¹ (log-uniform) | D7: — | E7: ×(3–10) below p_b
A8: Bubble point | B8: p_b | C8: — | D8: — | E8: 1,500–3,500 psia (uniform)
A9: Effective half fracture spacing | B9: L | C9: 15–150 ft (log-uniform) | D9: 150–300 ft | E9: —
A10: Fracture half-length | B10: x_f | C10: 75–400 ft (uniform) | D10: — | E10: —
A11: Half well spacing | B11: Y_e | C11: x_f × U(1, 2.5), clipped to 100–600 ft, ≥ x_f | D11: — | E11: —
A12: Height | B12: h | C12: 50–150 ft (uniform) | D12: — | E12: —
A13: Fracture conductivity | B13: F_c | C13: 0.5–50 md·ft (log-uniform) | D13: — | E13: —
A14: Lateral length | B14: — | C14: 7,500–10,000 ft (uniform) | D14: — | E14: —
... A21: Shut-in simulated | B21: — | C21: 504 h | D21: — | E21: —

Sheet Results_by_Scenario
A1: Accuracy of every estimator by scenario and buildup duration
A3: Scenario | B3: N (h) | C3: Method | D3: Rows | E3: Undefined fraction | F3: Bias (median e) | G3: Median |e| | H3: 90th pct |e| | I3: Median |error| (psi) | J3: Within 10 % | K3: Within 25 % | L3: Interval coverage | M3: Interval width / deficit | N3: Fold s.d. of median |e| | O3: Fold s.d. of coverage
A4: S1 Main (5-fold CV, pooled) | B4: 24 | C4: proxy | D4: 2976 | E4: 0 | F4: -0.71159671 | G4: 0.7116883 | H4: 0.89859601 | I4: 858.23244 | J4: 0.011760753 | K4: 0.048051075 | N4: 0.011831546
A5: S1 Main (5-fold CV, pooled) | B5: 24 | C5: horner | D5: 2976 | E5: 0 | F5: -0.28700323 | G5: 0.43000676 | H5: 0.81104498 | I5: 345.4818 | J5: 0.11525538 | K5: 0.29200269 | N5: 0.020090709
A6: S1 Main (5-fold CV, pooled) | B6: 24 | C6: fmb | D6: 2976 | E6: 0.065524194 | F6: -0.24233429 | G6: 0.40599626 | H6: 1.3579672 | I6: 313.99721 | J6: 0.11424731 | K6: 0.28797043 | N6: 0.010489304
A7: S1 Main (5-fold CV, pooled) | B7: 24 | C7: sqrt | D7: 2976 | E7: 0.065524194 | F7: 0.22598059 | G7: 0.46624824 | H7: 1.5560817 | I7: 367.00448 | J7: 0.11424731 | K7: 0.27688172 | N7: 0.049560009
A8: S1 Main (5-fold CV, pooled) | B8: 24 | C8: slab | D8: 2976 | E8: 0.065524194 | F8: 0.51600258 | G8: 0.65902815 | H8: 2.347663 | I8: 560.39748 | J8: 0.078965054 | K8: 0.19422043 | N8: 0.026954332
A9: S1 Main (5-fold CV, pooled) | B9: 24 | C9: ml_data | D9: 2976 | E9: 0 | F9: -0.0013733464 | G9: 0.17495105 | H9: 0.46836288 | I9: 150.21545 | J9: 0.30073925 | K9: 0.65456989 | N9: 0.0029155626
A10: S1 Main (5-fold CV, pooled) | B10: 24 | C10: ml_phys | D10: 2976 | E10: 0 | F10: 0.0012110685 | G10: 0.15860318 | H10: 0.42626379 | I10: 129.35694 | J10: 0.34173387 | K10: 0.6999328 | N10: 0.0076952703
A11: S1 Main (5-fold CV, pooled) | B11: 24 | C11: ml_phys_interval | D11: 2976 | L11: 0.80040323 | M11: 0.66503429 | O11: 0.025133593
A12: S1 Main (5-fold CV, pooled) | B12: 72 | C12: proxy | D12: 2981 | E12: 0 | F12: -0.5789101 | G12: 0.58350738 | H12: 0.82610004 | I12: 695.39363 | J12: 0.048641396 | K12: 0.12546125 | N12: 0.014172993
A13: S1 Main (5-fold CV, pooled) | B13: 72 | C13: horner | D13: 2981 | E13: 0 | F13: -0.1150942 | G13: 0.37585559 | H13: 0.97216473 | I13: 212.34499 | J13: 0.12814492 | K13: 0.33713519 | N13: 0.011724023
A14: S1 Main (5-fold CV, pooled) | B14: 72 | C14: fmb | D14: 2981 | E14: 0.069439785 | F14: -0.23428342 | G14: 0.40938035 | H14: 1.478279 | I14: 316.431 | J14: 0.11137202 | K14: 0.27943643 | N14: 0.012854673
A15: S1 Main (5-fold CV, pooled) | B15: 72 | C15: sqrt | D15: 2981 | E15: 0.069775243 | F15: 0.023189851 | G15: 0.36500452 | H15: 0.97287377 | I15: 278.13565 | J15: 0.1338477 | K15: 0.33914794 | N15: 0.026182007
A16: S1 Main (5-fold CV, pooled) | B16: 72 | C16: slab | D16: 2981 | E16: 0.069439785 | F16: 0.37664421 | G16: 0.53329708 | H16: 1.7286282 | I16: 414.44483 | J16: 0.10030191 | K16: 0.23716874 | N16: 0.029957432
A17: S1 Main (5-fold CV, pooled) | B17: 72 | C17: ml_data | D17: 2981 | E17: 0 | F17: 0.0088045793 | G17: 0.15707986 | H17: 0.42295407 | I17: 128.02024 | J17: 0.3418316 | K17: 0.69775243 | N17: 0.0071417923
A18: S1 Main (5-fold CV, pooled) | B18: 72 | C18: ml_phys | D18: 2981 | E18: 0 | F18: 0.0025850044 | G18: 0.14392394 | H18: 0.40178636 | I18: 119.89619 | J18: 0.36564911 | K18: 0.74303925 | N18: 0.0039642198
A19: S1 Main (5-fold CV, pooled) | B19: 72 | C19: ml_phys_interval | D19: 2981 | L19: 0.80073801 | M19: 0.62090438 | O19: 0.023488247
A20: S1 Main (5-fold CV, pooled) | B20: 168 | C20: proxy | D20: 2985 | E20: 0 | F20: -0.44888543 | G20: 0.473383 | H20: 0.76257147 | I20: 530.61265 | J20: 0.069681742 | K20: 0.20167504 | N20: 0.014386417
A21: S1 Main (5-fold CV, pooled) | B21: 168 | C21: horner | D21: 2985 | E21: 0 | F21: 0.021006062 | G21: 0.3655933 | H21: 1.3099082 | I21: 214.7257 | J21: 0.14639866 | K21: 0.36080402 | N21: 0.018659371
A22: S1 Main (5-fold CV, pooled) | B22: 168 | C22: fmb | D22: 2985 | E22: 0.071021776 | F22: -0.23355584 | G22: 0.4117236 | H22: 1.4035442 | I22: 311.01321 | J22: 0.10854271 | K22: 0.28274707 | N22: 0.016423849
A23: S1 Main (5-fold CV, pooled) | B23: 168 | C23: sqrt | D23: 2985 | E23: 0.071021776 | F23: -0.12499961 | G23: 0.33143379 | H23: 0.78704243 | I23: 257.23972 | J23: 0.15175879 | K23: 0.35946399 | N23: 0.016882734
A24: S1 Main (5-fold CV, pooled) | B24: 168 | C24: slab | D24: 2985 | E24: 0.071021776 | F24: 0.27544975 | G24: 0.45442829 | H24: 1.4206632 | I24: 334.13526 | J24: 0.12462312 | K24: 0.29078727 | N24: 0.040319592
A25: S1 Main (5-fold CV, pooled) | B25: 168 | C25: ml_data | D25: 2985 | E25: 0 | F25: 0.011223797 | G25: 0.14733391 | H25: 0.39854856 | I25: 119.37107 | J25: 0.36448911 | K25: 0.74204355 | N25: 0.0053726194
A26: S1 Main (5-fold CV, pooled) | B26: 168 | C26: ml_phys | D26: 2985 | E26: 0 | F26: 0.0079875448 | G26: 0.1389417 | H26: 0.37859034 | I26: 112.16392 | J26: 0.38157454 | K26: 0.75175879 | N26: 0.0077134919
A27: S1 Main (5-fold CV, pooled) | B27: 168 | C27: ml_phys_interval | D27: 2985 | L27: 0.81909548 | M27: 0.61422108 | O27: 0.024244748
A28: S2 Nonlinear | B28: 24 | C28: proxy | D28: 160 | E28: 0 | F28: -0.78950283 | G28: 0.78950283 | H28: 0.92671902 | I28: 1086.5243 | J28: 0 | K28: 0
A29: S2 Nonlinear | B29: 24 | C29: horner | D29: 160 | E29: 0 | F29: -0.51205947 | G29: 0.51205947 | H29: 0.80719475 | I29: 690.12587 | J29: 0.075 | K29: 0.2125
A30: S2 Nonlinear | B30: 24 | C30: fmb | D30: 160 | E30: 0.06875 | F30: -0.023871691 | G30: 0.39880015 | H30: 2.0450799 | I30: 491.56935 | J30: 0.125 | K30: 0.325
A31: S2 Nonlinear | B31: 24 | C31: sqrt | D31: 160 | E31: 0.06875 | F31: 0.13103293 | G31: 0.47985868 | H31: 1.1299988 | I31: 631.80462 | J31: 0.0625 | K31: 0.2125
A32: S2 Nonlinear | B32: 24 | C32: slab | D32: 160 | E32: 0.06875 | F32: 0.36357578 | G32: 0.62080828 | H32: 2.1905076 | I32: 718.30105 | J32: 0.075 | K32: 0.2
A33: S2 Nonlinear | B33: 24 | C33: ml_data | D33: 160 | E33: 0 | F33: -0.13302485 | G33: 0.31639318 | H33: 0.561545 | I33: 293.63828 | J33: 0.16875 | K33: 0.4125
A34: S2 Nonlinear | B34: 24 | C34: ml_phys | D34: 160 | E34: 0 | F34: 0.017105929 | G34: 0.26938445 | H34: 0.70132796 | I34: 339.71453 | J34: 0.1875 | K34: 0.45625
A35: S2 Nonlinear | B35: 24 | C35: ml_phys_interval | D35: 160 | L35: 0.64375 | M35: 0.63977132
A36: S2 Nonlinear | B36: 72 | C36: proxy | D36: 160 | E36: 0 | F36: -0.69371189 | G36: 0.69371189 | H36: 0.8713358 | I36: 961.49228 | J36: 0.00625 | K36: 0.025
A37: S2 Nonlinear | B37: 72 | C37: horner | D37: 160 | E37: 0 | F37: -0.33661526 | G37: 0.38536867 | H37: 0.72935105 | I37: 470.76766 | J37: 0.13125 | K37: 0.3125
A38: S2 Nonlinear | B38: 72 | C38: fmb | D38: 160 | E38: 0.0625 | F38: -0.0054650298 | G38: 0.43540402 | H38: 1.6187475 | I38: 548.4988 | J38: 0.1 | K38: 0.25
A39: S2 Nonlinear | B39: 72 | C39: sqrt | D39: 160 | E39: 0.0625 | F39: -0.035900522 | G39: 0.3794197 | H39: 0.78510857 | I39: 494.44101 | J39: 0.125 | K39: 0.30625
A40: S2 Nonlinear | B40: 72 | C40: slab | D40: 160 | E40: 0.0625 | F40: 0.26994667 | G40: 0.48823137 | H40: 1.6169045 | I40: 613.52207 | J40: 0.1125 | K40: 0.225
A41: S2 Nonlinear | B41: 72 | C41: ml_data | D41: 160 | E41: 0 | F41: -0.13419536 | G41: 0.2398844 | H41: 0.51139599 | I41: 248.45578 | J41: 0.24375 | K41: 0.5125
...

Sheet Summary
A1: Headline comparison (formulas reading Results_by_Scenario)
A3: Scenario | B3: N (h) | C3: Proxy median |e| | D3: Best physics median |e| | E3: ML-D median |e| | F3: ML-P median |e| | G3: ML-P bias | H3: ML-P reduction vs proxy | I3: ML-P reduction vs best physics | J3: ML-P interval coverage
A4: S1 Main (5-fold CV, pooled) | B4: 24 | C4: =SUMIFS(Results_by_Scenario!$G$4:$G$75,Results_by_Scenario!$A$4:$A$75,$A4,Results_by_Scenario!$B$4:$B$75,$B4,Results_by_Scenario!$C$4:$C$75,"proxy") -> 0.7116883 | D4: =MIN(SUMIFS(Results_by_Scenario!$G$4:$G$75,Results_by_Scenario!$A$4:$A$75,$A4,Results_by_Scenario!$B$4:$B$75,$B4,Results_by_Scenario!$C$4:$C$75,"horner"),SUMIFS(Results_by_Scenario!$G$4:$G$75,Results_by_Scenario!$A$4:$A$75,$A4,Results_by_Scenario!$B$4:$B$75,$B4,Results_by_Scenario!$C$4:$C$75,"fmb"),SUMIFS(Results_by_Scenario!$G$4:$G$75,Results_by_Scenario!$A$4:$A$75,$A4,Results_by_Scenario!$B$4:$B$75,$B4,Results_by_Scenario!$C$4:$C$75,"sqrt"),SUMIFS(Results_by_Scenario!$G$4:$G$75,Results_by_Scenario!$A$4:$A$75,$A4,Results_by_Scenario!$B$4:$B$75,$B4,Results_by_Scenario!$C$4:$C$75,"slab")) -> 0.40599626 | E4: =SUMIFS(Results_by_Scenario!$G$4:$G$75,Results_by_Scenario!$A$4:$A$75,$A4,Results_by_Scenario!$B$4:$B$75,$B4,Results_by_Scenario!$C$4:$C$75,"ml_data") -> 0.17495105 | F4: =SUMIFS(Results_by_Scenario!$G$4:$G$75,Results_by_Scenario!$A$4:$A$75,$A4,Results_by_Scenario!$B$4:$B$75,$B4,Results_by_Scenario!$C$4:$C$75,"ml_phys") -> 0.15860318 | G4: =SUMIFS(Results_by_Scenario!$F$4:$F$75,Results_by_Scenario!$A$4:$A$75,$A4,Results_by_Scenario!$B$4:$B$75,$B4,Results_by_Scenario!$C$4:$C$75,"ml_phys") -> 0.0012110685 | H4: =IF(C4>0,1-F4/C4,"") -> 0.77714516 | I4: =IF(D4>0,1-F4/D4,"") -> 0.60934817 | J4: =SUMIFS(Results_by_Scenario!$L$4:$L$75,Results_by_Scenario!$A$4:$A$75,$A4,Results_by_Scenario!$B$4:$B$75,$B4,Results_by_Scenario!$C$4:$C$75,"ml_phys_interval") -> 0.80040323
A5: S1 Main (5-fold CV, pooled) | B5: 72 | C5: =SUMIFS(Results_by_Scenario!$G$4:$G$75,Results_by_Scenario!$A$4:$A$75,$A5,Results_by_Scenario!$B$4:$B$75,$B5,Results_by_Scenario!$C$4:$C$75,"proxy") -> 0.58350738 | D5: =MIN(SUMIFS(Results_by_Scenario!$G$4:$G$75,Results_by_Scenario!$A$4:$A$75,$A5,Results_by_Scenario!$B$4:$B$75,$B5,Results_by_Scenario!$C$4:$C$75,"horner"),SUMIFS(Results_by_Scenario!$G$4:$G$75,Results_by_Scenario!$A$4:$A$75,$A5,Results_by_Scenario!$B$4:$B$75,$B5,Results_by_Scenario!$C$4:$C$75,"fmb"),SUMIFS(Results_by_Scenario!$G$4:$G$75,Results_by_Scenario!$A$4:$A$75,$A5,Results_by_Scenario!$B$4:$B$75,$B5,Results_by_Scenario!$C$4:$C$75,"sqrt"),SUMIFS(Results_by_Scenario!$G$4:$G$75,Results_by_Scenario!$A$4:$A$75,$A5,Results_by_Scenario!$B$4:$B$75,$B5,Results_by_Scenario!$C$4:$C$75,"slab")) -> 0.36500452 | E5: =SUMIFS(Results_by_Scenario!$G$4:$G$75,Results_by_Scenario!$A$4:$A$75,$A5,Results_by_Scenario!$B$4:$B$75,$B5,Results_by_Scenario!$C$4:$C$75,"ml_data") -> 0.15707986 | F5: =SUMIFS(Results_by_Scenario!$G$4:$G$75,Results_by_Scenario!$A$4:$A$75,$A5,Results_by_Scenario!$B$4:$B$75,$B5,Results_by_Scenario!$C$4:$C$75,"ml_phys") -> 0.14392394 | G5: =SUMIFS(Results_by_Scenario!$F$4:$F$75,Results_by_Scenario!$A$4:$A$75,$A5,Results_by_Scenario!$B$4:$B$75,$B5,Results_by_Scenario!$C$4:$C$75,"ml_phys") -> 0.0025850044 | H5: =IF(C5>0,1-F5/C5,"") -> 0.75334684 | I5: =IF(D5>0,1-F5/D5,"") -> 0.60569272 | J5: =SUMIFS(Results_by_Scenario!$L$4:$L$75,Results_by_Scenario!$A$4:$A$75,$A5,Results_by_Scenario!$B$4:$B$75,$B5,Results_by_Scenario!$C$4:$C$75,"ml_phys_interval") -> 0.80073801
A6: S1 Main (5-fold CV, pooled) | B6: 168 | C6: =SUMIFS(Results_by_Scenario!$G$4:$G$75,Results_by_Scenario!$A$4:$A$75,$A6,Results_by_Scenario!$B$4:$B$75,$B6,Results_by_Scenario!$C$4:$C$75,"proxy") -> 0.473383 | D6: =MIN(SUMIFS(Results_by_Scenario!$G$4:$G$75,Results_by_Scenario!$A$4:$A$75,$A6,Results_by_Scenario!$B$4:$B$75,$B6,Results_by_Scenario!$C$4:$C$75,"horner"),SUMIFS(Results_by_Scenario!$G$4:$G$75,Results_by_Scenario!$A$4:$A$75,$A6,Results_by_Scenario!$B$4:$B$75,$B6,Results_by_Scenario!$C$4:$C$75,"fmb"),SUMIFS(Results_by_Scenario!$G$4:$G$75,Results_by_Scenario!$A$4:$A$75,$A6,Results_by_Scenario!$B$4:$B$75,$B6,Results_by_Scenario!$C$4:$C$75,"sqrt"),SUMIFS(Results_by_Scenario!$G$4:$G$75,Results_by_Scenario!$A$4:$A$75,$A6,Results_by_Scenario!$B$4:$B$75,$B6,Results_by_Scenario!$C$4:$C$75,"slab")) -> 0.33143379 | E6: =SUMIFS(Results_by_Scenario!$G$4:$G$75,Results_by_Scenario!$A$4:$A$75,$A6,Results_by_Scenario!$B$4:$B$75,$B6,Results_by_Scenario!$C$4:$C$75,"ml_data") -> 0.14733391 | F6: =SUMIFS(Results_by_Scenario!$G$4:$G$75,Results_by_Scenario!$A$4:$A$75,$A6,Results_by_Scenario!$B$4:$B$75,$B6,Results_by_Scenario!$C$4:$C$75,"ml_phys") -> 0.1389417 | G6: =SUMIFS(Results_by_Scenario!$F$4:$F$75,Results_by_Scenario!$A$4:$A$75,$A6,Results_by_Scenario!$B$4:$B$75,$B6,Results_by_Scenario!$C$4:$C$75,"ml_phys") -> 0.0079875448 | H6: =IF(C6>0,1-F6/C6,"") -> 0.70649198 | I6: =IF(D6>0,1-F6/D6,"") -> 0.58078594 | J6: =SUMIFS(Results_by_Scenario!$L$4:$L$75,Results_by_Scenario!$A$4:$A$75,$A6,Results_by_Scenario!$B$4:$B$75,$B6,Results_by_Scenario!$C$4:$C$75,"ml_phys_interval") -> 0.81909548
A7: S2 Nonlinear | B7: 24 | C7: =SUMIFS(Results_by_Scenario!$G$4:$G$75,Results_by_Scenario!$A$4:$A$75,$A7,Results_by_Scenario!$B$4:$B$75,$B7,Results_by_Scenario!$C$4:$C$75,"proxy") -> 0.78950283 | D7: =MIN(SUMIFS(Results_by_Scenario!$G$4:$G$75,Results_by_Scenario!$A$4:$A$75,$A7,Results_by_Scenario!$B$4:$B$75,$B7,Results_by_Scenario!$C$4:$C$75,"horner"),SUMIFS(Results_by_Scenario!$G$4:$G$75,Results_by_Scenario!$A$4:$A$75,$A7,Results_by_Scenario!$B$4:$B$75,$B7,Results_by_Scenario!$C$4:$C$75,"fmb"),SUMIFS(Results_by_Scenario!$G$4:$G$75,Results_by_Scenario!$A$4:$A$75,$A7,Results_by_Scenario!$B$4:$B$75,$B7,Results_by_Scenario!$C$4:$C$75,"sqrt"),SUMIFS(Results_by_Scenario!$G$4:$G$75,Results_by_Scenario!$A$4:$A$75,$A7,Results_by_Scenario!$B$4:$B$75,$B7,Results_by_Scenario!$C$4:$C$75,"slab")) -> 0.39880015 | E7: =SUMIFS(Results_by_Scenario!$G$4:$G$75,Results_by_Scenario!$A$4:$A$75,$A7,Results_by_Scenario!$B$4:$B$75,$B7,Results_by_Scenario!$C$4:$C$75,"ml_data") -> 0.31639318 | F7: =SUMIFS(Results_by_Scenario!$G$4:$G$75,Results_by_Scenario!$A$4:$A$75,$A7,Results_by_Scenario!$B$4:$B$75,$B7,Results_by_Scenario!$C$4:$C$75,"ml_phys") -> 0.26938445 | G7: =SUMIFS(Results_by_Scenario!$F$4:$F$75,Results_by_Scenario!$A$4:$A$75,$A7,Results_by_Scenario!$B$4:$B$75,$B7,Results_by_Scenario!$C$4:$C$75,"ml_phys") -> 0.017105929 | H7: =IF(C7>0,1-F7/C7,"") -> 0.65879229 | I7: =IF(D7>0,1-F7/D7,"") -> 0.32451266 | J7: =SUMIFS(Results_by_Scenario!$L$4:$L$75,Results_by_Scenario!$A$4:$A$75,$A7,Results_by_Scenario!$B$4:$B$75,$B7,Results_by_Scenario!$C$4:$C$75,"ml_phys_interval") -> 0.64375
A8: S2 Nonlinear | B8: 72 | C8: =SUMIFS(Results_by_Scenario!$G$4:$G$75,Results_by_Scenario!$A$4:$A$75,$A8,Results_by_Scenario!$B$4:$B$75,$B8,Results_by_Scenario!$C$4:$C$75,"proxy") -> 0.69371189 | D8: =MIN(SUMIFS(Results_by_Scenario!$G$4:$G$75,Results_by_Scenario!$A$4:$A$75,$A8,Results_by_Scenario!$B$4:$B$75,$B8,Results_by_Scenario!$C$4:$C$75,"horner"),SUMIFS(Results_by_Scenario!$G$4:$G$75,Results_by_Scenario!$A$4:$A$75,$A8,Results_by_Scenario!$B$4:$B$75,$B8,Results_by_Scenario!$C$4:$C$75,"fmb"),SUMIFS(Results_by_Scenario!$G$4:$G$75,Results_by_Scenario!$A$4:$A$75,$A8,Results_by_Scenario!$B$4:$B$75,$B8,Results_by_Scenario!$C$4:$C$75,"sqrt"),SUMIFS(Results_by_Scenario!$G$4:$G$75,Results_by_Scenario!$A$4:$A$75,$A8,Results_by_Scenario!$B$4:$B$75,$B8,Results_by_Scenario!$C$4:$C$75,"slab")) -> 0.3794197 | E8: =SUMIFS(Results_by_Scenario!$G$4:$G$75,Results_by_Scenario!$A$4:$A$75,$A8,Results_by_Scenario!$B$4:$B$75,$B8,Results_by_Scenario!$C$4:$C$75,"ml_data") -> 0.2398844 | F8: =SUMIFS(Results_by_Scenario!$G$4:$G$75,Results_by_Scenario!$A$4:$A$75,$A8,Results_by_Scenario!$B$4:$B$75,$B8,Results_by_Scenario!$C$4:$C$75,"ml_phys") -> 0.2444394 | G8: =SUMIFS(Results_by_Scenario!$F$4:$F$75,Results_by_Scenario!$A$4:$A$75,$A8,Results_by_Scenario!$B$4:$B$75,$B8,Results_by_Scenario!$C$4:$C$75,"ml_phys") -> 0.035590296 | H8: =IF(C8>0,1-F8/C8,"") -> 0.64763556 | I8: =IF(D8>0,1-F8/D8,"") -> 0.35575459 | J8: =SUMIFS(Results_by_Scenario!$L$4:$L$75,Results_by_Scenario!$A$4:$A$75,$A8,Results_by_Scenario!$B$4:$B$75,$B8,Results_by_Scenario!$C$4:$C$75,"ml_phys_interval") -> 0.6625
A9: S2 Nonlinear | B9: 168 | C9: =SUMIFS(Results_by_Scenario!$G$4:$G$75,Results_by_Scenario!$A$4:$A$75,$A9,Results_by_Scenario!$B$4:$B$75,$B9,Results_by_Scenario!$C$4:$C$75,"proxy") -> 0.58857632 | D9: =MIN(SUMIFS(Results_by_Scenario!$G$4:$G$75,Results_by_Scenario!$A$4:$A$75,$A9,Results_by_Scenario!$B$4:$B$75,$B9,Results_by_Scenario!$C$4:$C$75,"horner"),SUMIFS(Results_by_Scenario!$G$4:$G$75,Results_by_Scenario!$A$4:$A$75,$A9,Results_by_Scenario!$B$4:$B$75,$B9,Results_by_Scenario!$C$4:$C$75,"fmb"),SUMIFS(Results_by_Scenario!$G$4:$G$75,Results_by_Scenario!$A$4:$A$75,$A9,Results_by_Scenario!$B$4:$B$75,$B9,Results_by_Scenario!$C$4:$C$75,"sqrt"),SUMIFS(Results_by_Scenario!$G$4:$G$75,Results_by_Scenario!$A$4:$A$75,$A9,Results_by_Scenario!$B$4:$B$75,$B9,Results_by_Scenario!$C$4:$C$75,"slab")) -> 0.32247985 | E9: =SUMIFS(Results_by_Scenario!$G$4:$G$75,Results_by_Scenario!$A$4:$A$75,$A9,Results_by_Scenario!$B$4:$B$75,$B9,Results_by_Scenario!$C$4:$C$75,"ml_data") -> 0.24347519 | F9: =SUMIFS(Results_by_Scenario!$G$4:$G$75,Results_by_Scenario!$A$4:$A$75,$A9,Results_by_Scenario!$B$4:$B$75,$B9,Results_by_Scenario!$C$4:$C$75,"ml_phys") -> 0.22144296 | G9: =SUMIFS(Results_by_Scenario!$F$4:$F$75,Results_by_Scenario!$A$4:$A$75,$A9,Results_by_Scenario!$B$4:$B$75,$B9,Results_by_Scenario!$C$4:$C$75,"ml_phys") -> 0.02263178 | H9: =IF(C9>0,1-F9/C9,"") -> 0.62376509 | I9: =IF(D9>0,1-F9/D9,"") -> 0.31331225 | J9: =SUMIFS(Results_by_Scenario!$L$4:$L$75,Results_by_Scenario!$A$4:$A$75,$A9,Results_by_Scenario!$B$4:$B$75,$B9,Results_by_Scenario!$C$4:$C$75,"ml_phys_interval") -> 0.66875
A10: S3 Extrapolation | B10: 24 | C10: =SUMIFS(Results_by_Scenario!$G$4:$G$75,Results_by_Scenario!$A$4:$A$75,$A10,Results_by_Scenario!$B$4:$B$75,$B10,Results_by_Scenario!$C$4:$C$75,"proxy") -> 0.70924025 | D10: =MIN(SUMIFS(Results_by_Scenario!$G$4:$G$75,Results_by_Scenario!$A$4:$A$75,$A10,Results_by_Scenario!$B$4:$B$75,$B10,Results_by_Scenario!$C$4:$C$75,"horner"),SUMIFS(Results_by_Scenario!$G$4:$G$75,Results_by_Scenario!$A$4:$A$75,$A10,Results_by_Scenario!$B$4:$B$75,$B10,Results_by_Scenario!$C$4:$C$75,"fmb"),SUMIFS(Results_by_Scenario!$G$4:$G$75,Results_by_Scenario!$A$4:$A$75,$A10,Results_by_Scenario!$B$4:$B$75,$B10,Results_by_Scenario!$C$4:$C$75,"sqrt"),SUMIFS(Results_by_Scenario!$G$4:$G$75,Results_by_Scenario!$A$4:$A$75,$A10,Results_by_Scenario!$B$4:$B$75,$B10,Results_by_Scenario!$C$4:$C$75,"slab")) -> 0.24118209 | E10: =SUMIFS(Results_by_Scenario!$G$4:$G$75,Results_by_Scenario!$A$4:$A$75,$A10,Results_by_Scenario!$B$4:$B$75,$B10,Results_by_Scenario!$C$4:$C$75,"ml_data") -> 0.18554251 | F10: =SUMIFS(Results_by_Scenario!$G$4:$G$75,Results_by_Scenario!$A$4:$A$75,$A10,Results_by_Scenario!$B$4:$B$75,$B10,Results_by_Scenario!$C$4:$C$75,"ml_phys") -> 0.17030426 | G10: =SUMIFS(Results_by_Scenario!$F$4:$F$75,Results_by_Scenario!$A$4:$A$75,$A10,Results_by_Scenario!$B$4:$B$75,$B10,Results_by_Scenario!$C$4:$C$75,"ml_phys") -> 0.10555412 | H10: =IF(C10>0,1-F10/C10,"") -> 0.7598779 | I10: =IF(D10>0,1-F10/D10,"") -> 0.29387686 | J10: =SUMIFS(Results_by_Scenario!$L$4:$L$75,Results_by_Scenario!$A$4:$A$75,$A10,Results_by_Scenario!$B$4:$B$75,$B10,Results_by_Scenario!$C$4:$C$75,"ml_phys_interval") -> 0.75376884
A11: S3 Extrapolation | B11: 72 | C11: =SUMIFS(Results_by_Scenario!$G$4:$G$75,Results_by_Scenario!$A$4:$A$75,$A11,Results_by_Scenario!$B$4:$B$75,$B11,Results_by_Scenario!$C$4:$C$75,"proxy") -> 0.57449742 | D11: =MIN(SUMIFS(Results_by_Scenario!$G$4:$G$75,Results_by_Scenario!$A$4:$A$75,$A11,Results_by_Scenario!$B$4:$B$75,$B11,Results_by_Scenario!$C$4:$C$75,"horner"),SUMIFS(Results_by_Scenario!$G$4:$G$75,Results_by_Scenario!$A$4:$A$75,$A11,Results_by_Scenario!$B$4:$B$75,$B11,Results_by_Scenario!$C$4:$C$75,"fmb"),SUMIFS(Results_by_Scenario!$G$4:$G$75,Results_by_Scenario!$A$4:$A$75,$A11,Results_by_Scenario!$B$4:$B$75,$B11,Results_by_Scenario!$C$4:$C$75,"sqrt"),SUMIFS(Results_by_Scenario!$G$4:$G$75,Results_by_Scenario!$A$4:$A$75,$A11,Results_by_Scenario!$B$4:$B$75,$B11,Results_by_Scenario!$C$4:$C$75,"slab")) -> 0.20377321 | E11: =SUMIFS(Results_by_Scenario!$G$4:$G$75,Results_by_Scenario!$A$4:$A$75,$A11,Results_by_Scenario!$B$4:$B$75,$B11,Results_by_Scenario!$C$4:$C$75,"ml_data") -> 0.19238052 | F11: =SUMIFS(Results_by_Scenario!$G$4:$G$75,Results_by_Scenario!$A$4:$A$75,$A11,Results_by_Scenario!$B$4:$B$75,$B11,Results_by_Scenario!$C$4:$C$75,"ml_phys") -> 0.1702075 | G11: =SUMIFS(Results_by_Scenario!$F$4:$F$75,Results_by_Scenario!$A$4:$A$75,$A11,Results_by_Scenario!$B$4:$B$75,$B11,Results_by_Scenario!$C$4:$C$75,"ml_phys") -> 0.14838099 | H11: =IF(C11>0,1-F11/C11,"") -> 0.703728 | I11: =IF(D11>0,1-F11/D11,"") -> 0.16472091 | J11: =SUMIFS(Results_by_Scenario!$L$4:$L$75,Results_by_Scenario!$A$4:$A$75,$A11,Results_by_Scenario!$B$4:$B$75,$B11,Results_by_Scenario!$C$4:$C$75,"ml_phys_interval") -> 0.72864322
A12: S3 Extrapolation | B12: 168 | C12: =SUMIFS(Results_by_Scenario!$G$4:$G$75,Results_by_Scenario!$A$4:$A$75,$A12,Results_by_Scenario!$B$4:$B$75,$B12,Results_by_Scenario!$C$4:$C$75,"proxy") -> 0.44726075 | D12: =MIN(SUMIFS(Results_by_Scenario!$G$4:$G$75,Results_by_Scenario!$A$4:$A$75,$A12,Results_by_Scenario!$B$4:$B$75,$B12,Results_by_Scenario!$C$4:$C$75,"horner"),SUMIFS(Results_by_Scenario!$G$4:$G$75,Results_by_Scenario!$A$4:$A$75,$A12,Results_by_Scenario!$B$4:$B$75,$B12,Results_by_Scenario!$C$4:$C$75,"fmb"),SUMIFS(Results_by_Scenario!$G$4:$G$75,Results_by_Scenario!$A$4:$A$75,$A12,Results_by_Scenario!$B$4:$B$75,$B12,Results_by_Scenario!$C$4:$C$75,"sqrt"),SUMIFS(Results_by_Scenario!$G$4:$G$75,Results_by_Scenario!$A$4:$A$75,$A12,Results_by_Scenario!$B$4:$B$75,$B12,Results_by_Scenario!$C$4:$C$75,"slab")) -> 0.17387953 | E12: =SUMIFS(Results_by_Scenario!$G$4:$G$75,Results_by_Scenario!$A$4:$A$75,$A12,Results_by_Scenario!$B$4:$B$75,$B12,Results_by_Scenario!$C$4:$C$75,"ml_data") -> 0.17015228 | F12: =SUMIFS(Results_by_Scenario!$G$4:$G$75,Results_by_Scenario!$A$4:$A$75,$A12,Results_by_Scenario!$B$4:$B$75,$B12,Results_by_Scenario!$C$4:$C$75,"ml_phys") -> 0.17536846 | G12: =SUMIFS(Results_by_Scenario!$F$4:$F$75,Results_by_Scenario!$A$4:$A$75,$A12,Results_by_Scenario!$B$4:$B$75,$B12,Results_by_Scenario!$C$4:$C$75,"ml_phys") -> 0.16012506 | H12: =IF(C12>0,1-F12/C12,"") -> 0.60790554 | I12: =IF(D12>0,1-F12/D12,"") -> -0.0085629943 | J12: =SUMIFS(Results_by_Scenario!$L$4:$L$75,Results_by_Scenario!$A$4:$A$75,$A12,Results_by_Scenario!$B$4:$B$75,$B12,Results_by_Scenario!$C$4:$C$75,"ml_phys_interval") -> 0.69849246
A14: Best physics = the lowest median |e| among Horner, FMB, square-root decline and slab inversion for that scenario and duration.

Sheet Initial_Pressure_Sensitivity
A1: Initial-pressure error 8 % vs 15 % (held-out cases of the selection split, models fitted on training + validation)
A3: p_i error | B3: N (h) | C3: Method | D3: Rows | E3: Undefined fraction | F3: Bias (median e) | G3: Median |e| | H3: 90th pct |e| | I3: Median |error| (psi) | J3: Within 10 %
A4: 8 % (S1) | B4: 24 | C4: proxy | D4: 446 | E4: 0 | F4: -0.739 | G4: 0.739 | H4: 0.906 | I4: 1175.338 | J4: 0.016
A5: 8 % (S1) | B5: 24 | C5: horner | D5: 446 | E5: 0 | F5: -0.336 | G5: 0.479 | H5: 0.844 | I5: 486.302 | J5: 0.078
A6: 8 % (S1) | B6: 24 | C6: fmb | D6: 446 | E6: 0.085 | F6: -0.3 | G6: 0.424 | H6: 1.144 | I6: 394.363 | J6: 0.103
A7: 8 % (S1) | B7: 24 | C7: sqrt | D7: 446 | E7: 0.085 | F7: 0.172 | G7: 0.489 | H7: 1.691 | I7: 539.707 | J7: 0.103
A8: 8 % (S1) | B8: 24 | C8: slab | D8: 446 | E8: 0.085 | F8: 0.463 | G8: 0.65 | H8: 2.359 | I8: 599.825 | J8: 0.072
A9: 8 % (S1) | B9: 24 | C9: ml_data | D9: 446 | E9: 0 | F9: 0.004 | G9: 0.178 | H9: 0.451 | I9: 161.853 | J9: 0.334
A10: 8 % (S1) | B10: 24 | C10: ml_phys | D10: 446 | E10: 0 | F10: -0.002 | G10: 0.172 | H10: 0.419 | I10: 149.922 | J10: 0.339
A11: 8 % (S1) | B11: 72 | C11: proxy | D11: 448 | E11: 0 | F11: -0.601 | G11: 0.604 | H11: 0.836 | I11: 990.053 | J11: 0.054
A12: 8 % (S1) | B12: 72 | C12: horner | D12: 448 | E12: 0 | F12: -0.146 | G12: 0.423 | H12: 1.108 | I12: 257.024 | J12: 0.143
A13: 8 % (S1) | B13: 72 | C13: fmb | D13: 448 | E13: 0.078 | F13: -0.233 | G13: 0.425 | H13: 1.671 | I13: 397.445 | J13: 0.109
A14: 8 % (S1) | B14: 72 | C14: sqrt | D14: 448 | E14: 0.078 | F14: 0.002 | G14: 0.403 | H14: 0.985 | I14: 338.147 | J14: 0.138
A15: 8 % (S1) | B15: 72 | C15: slab | D15: 448 | E15: 0.078 | F15: 0.351 | G15: 0.541 | H15: 1.745 | I15: 491.552 | J15: 0.087
... A45: 15 % (S4) | B45: 168 | C45: ml_phys | D45: 448 | E45: 0 | F45: 0 | G45: 0.151 | H45: 0.397 | I45: 144.684 | J45: 0.359

Sheet Field_Scenarios
A1: HFTS-1 Monte Carlo estimates (psia) per well and buildup duration; 300 draws of p_i, pad-decline variant and rate noise
A3: Well | B3: N (h) | C3: Buildup length (h) | D3: t_p (d) | E3: p_wf | F3: p_ws(N) | G3: Core well 6TW | H3: Horner P50 | I3: FMB P10 | J3: FMB P50 | K3: FMB P90 | L3: Sq.-root P10 | M3: Sq.-root P50 | N3: Sq.-root P90 | O3: Slab P50 | P3: ML-D P10 | Q3: ML-D P50 | R3: ML-D P90 | S3: ML-P P50 | T3: ML-P 80 % low | U3: ML-P 80 % high | V3: Flag: P50 outside quantile band | W3: D (10⁻³/d)
A4: 3SU | B4: 24 | C4: 36 | D4: 216.7 | E4: 767.16998 | F4: 1037.4 | G4: 2848.4126 | H4: 1410.4705 | I4: 2012.9181 | J4: 2468.3668 | K4: 3026.5611 | L4: 2448.2245 | M4: 2868.774 | N4: 3521.8376 | O4: 3588.5083 | P4: 1925.9222 | Q4: 2138.8613 | R4: 2421.676 | S4: 2891.1148 | T4: 1910.952 | U4: 3730.7247 | V4: no | W4: 3.5594219
A5: 3SU | B5: 36 | C5: 36 | D5: 216.7 | E5: 767.16998 | F5: 1090.4787 | G5: 2848.4126 | H5: 1495.2628 | I5: 1995.6567 | J5: 2450.8446 | K5: 3041.4767 | L5: 2435.5046 | M5: 2809.2271 | N5: 3512.3788 | O5: 3402.9214 | P5: 2328.0421 | Q5: 2620.3915 | R5: 2995.0799 | S5: 3197.5963 | T5: 2019.6432 | U5: 3796.4284 | V5: no | W5: 3.7294021
A6: 4SM | B6: 24 | C6: 84.4 | D6: 208.2 | E6: 1070.575 | F6: 1206.3 | G6: 2844.1548 | H6: 1439.2715 | I6: 2047.0607 | J6: 2454.3222 | K6: 3015.0003 | L6: 2037.3021 | M6: 2245.7604 | N6: 2561.5856 | O6: 2283.069 | P6: 1772.0396 | Q6: 1917.4848 | R6: 2118.3307 | S6: 2680.2735 | T6: 1726.0636 | U6: 3266.7223 | V6: no | W6: 4.3859673
A7: 4SM | B7: 72 | C7: 84.4 | D7: 208.2 | E7: 1070.575 | F7: 1258.95 | G7: 2844.1548 | H7: 1486.6294 | I7: 2070.1387 | J7: 2490.9019 | K7: 3015.7309 | L7: 1703.4068 | M7: 1854.4889 | N7: 2094.0424 | O7: 2146.5073 | P7: 1374.9503 | Q7: 1410.7029 | R7: 1448.3268 | S7: 2267.0684 | T7: 1540.2676 | U7: 2267.0684 | V7: yes | W7: 4.3031524
A8: 5SM | B8: 24 | C8: 71.9 | D8: 203.8 | E8: 981.78247 | F8: 1200.7 | G8: 2838.9719 | H8: 1519.8602 | I8: 1642.0481 | J8: 1994.5981 | K8: 2506.5226 | L8: 2010.6009 | M8: 2231.0726 | N8: 2558.2466 | O8: 2634.6909 | P8: 1880.3712 | Q8: 2093.0694 | R8: 2261.1224 | S8: 2391.3959 | T8: 1472.3023 | U8: 3384.5866 | V8: no | W8: 6.9369044
A9: 5SM | B9: 71.9 | C9: 71.9 | D9: 203.8 | E9: 981.78247 | F9: 1273.5 | G9: 2838.9719 | H9: 1605.0574 | I9: 1656.0293 | J9: 2022.2971 | K9: 2493.3239 | L9: 1740.6079 | M9: 1912.2584 | N9: 2169.7364 | O9: 2394.7818 | P9: 1459.7985 | Q9: 1485.5128 | R9: 1527.2728 | S9: 1969.627 | T9: 1441.9027 | U9: 2137.2344 | V9: no | W9: 6.8300924
A10: 5SU | B10: 24 | C10: 71.6 | D10: 215.2 | E10: 798.56 | F10: 1104.2 | G10: 2836.0999 | H10: 1552.9232 | I10: 1361.3595 | J10: 1756.9422 | K10: 2277.5901 | L10: 2046.5388 | M10: 2444.6271 | N10: 2909.6823 | O10: 2935.2156 | P10: 2043.7883 | Q10: 2221.2596 | R10: 2636.0807 | S10: 2206.5739 | T10: 1527.3007 | U10: 3616.497 | V10: no | W10: 7.9118858
A11: 5SU | B11: 71.6 | C11: 71.6 | D11: 215.2 | E11: 798.56 | F11: 1192.7 | G11: 2836.0999 | H11: 1629.6247 | I11: 1368.0765 | J11: 1729.0164 | K11: 2232.4093 | L11: 1678.2578 | M11: 1907.9043 | N11: 2179.4548 | O11: 2568.4089 | P11: 1448.0732 | Q11: 1477.9459 | R11: 1531.3075 | S11: 1704.0302 | T11: 1402.4948 | U11: 2048.5988 | V11: no | W11: 8.043328
A12: 6SM | B12: 24 | C12: 71.5 | D12: 207.3 | E12: 760.30005 | F12: 1092 | G12: 2830.3159 | H12: 1538.3412 | I12: 1200.951 | J12: 1578.706 | K12: 2060.5835 | L12: 1847.589 | M12: 2181.7308 | N12: 2601.4329 | O12: 2830.4031 | P12: 2068.7504 | Q12: 2158.368 | R12: 2301.1412 | S12: 1909.3275 | T12: 1394.6033 | U12: 3267.063 | V12: no | W12: 10.57536
A13: 6SM | B13: 71.5 | C13: 71.5 | D13: 207.3 | E13: 760.30005 | F13: 1170 | G13: 2830.3159 | H13: 1627.1474 | I13: 1215.7519 | J13: 1577.4861 | K13: 2150.0692 | L13: 1519.857 | M13: 1748.2414 | N13: 2095.673 | O13: 2468.0277 | P13: 1408.3021 | Q13: 1438.1646 | R13: 1480.8821 | S13: 1579.8598 | T13: 1352.1367 | U13: 2026.3542 | V13: no | W13: 10.431876
A14: 6SU | B14: 24 | C14: 71.1 | D14: 219.5 | E14: 621.83496 | F14: 958.62 | G14: 2833.52 | H14: 1379.9859 | I14: 1154.8542 | J14: 1542.4134 | K14: 1932.5521 | L14: 1649.7199 | M14: 1977.0083 | N14: 2291.5489 | O14: 2760.5661 | P14: 1609.0843 | Q14: 1779.6505 | R14: 1923.6718 | S14: 1638.1417 | T14: 1226.916 | U14: 2916.4424 | V14: no | W14: 10.525213
A15: 6SU | B15: 71.1 | C15: 71.1 | D15: 219.5 | E15: 621.83496 | F15: 1082.4349 | G15: 2833.52 | H15: 1573.7021 | I15: 1137.4368 | J15: 1524.8932 | K15: 1936.4031 | L15: 1509.4055 | M15: 1790.9287 | N15: 2060.4202 | O15: 2407.775 | P15: 1272.8031 | Q15: 1298.9016 | R15: 1328.2599 | S15: 1489.1717 | T15: 1264.7793 | U15: 2089.1735 | V15: no | W15: 10.556834
... A23: 8SU | B23: 72 | C23: 84.2 | D23: 222.4 | E23: 677.64502 | F23: 1108.6 | G23: 2826.3911 | H23: 1519.403 | I23: 1308.1353 | J23: 1663.3186 | K23: 2188.2123 | L23: 1535.7591 | M23: 1736.0956 | N23: 2033.6965 | O23: 2577.0446 | P23: 1431.7861 | Q23: 1541.2609 | R23: 1626.7101 | S23: 1732.161 | T23: 1304.9808 | U23: 2225.1029 | V23: no | W23: 7.5662605

Sheet Field_Rate_Variants
A1: Pad oil rate (bbl/d) = lease 16507 total minus the extrapolated decline of the older wells
A2: Source: Railroad Commission of Texas Production Data Query, lease 16507 (raw file in 03_Raw_Data/field). Only the shape of the decline enters the estimators.
A3: Month | B3: Days | C3: Lease total | D3: Pad (slow base decline, ×0.5) | E3: Pad (central, 0.69 /yr) | F3: Pad (fast base decline, ×1.5)
A4: Jan 2016 | B4: 31 | C4: 7512.0323 | D4: 5103.9394 | E4: 5546.3935 | F4: 5907.5527
A5: Feb 2016 | B5: 29 | C5: 7614.8276 | D5: 5276.577 | E5: 5761.5547 | F5: 6145.943
A6: Mar 2016 | B6: 31 | C6: 5952.129 | D6: 3677.3798 | E6: 4198.1503 | F6: 4599.698
A7: Apr 2016 | B7: 30 | C7: 4863.7333 | D7: 2654.9589 | E7: 3210.021 | F7: 3625.5966
A8: May 2016 | B8: 31 | C8: 4330.9032 | D8: 2184.153 | E8: 2768.762 | F8: 3194.1687
A9: Jun 2016 | B9: 30 | C9: 4499.5 | D9: 2415.0123 | E9: 3026.6588 | F9: 3458.8312
A10: Jul 2016 | B10: 31 | C10: 4156.129 | D10: 2130.1754 | E10: 2764.8436 | F10: 3200.69
A11: Aug 2016 | B11: 31 | C11: 3671.7097 | D11: 1704.5151 | E11: 2359.9572 | F11: 2797.015
A12: Sep 2016 | B12: 30 | C12: 3392.4 | D12: 1482.2602 | E12: 2155.634 | F12: 2591.626
